28/11/22 (02:13:59) | INFO: Loglevel set to INFO
28/11/22 (10:38:25) | ERROR: <urlopen error [Errno -3] Temporary failure in name resolution>
Traceback (most recent call last):
  File "/usr/lib/python3.10/urllib/request.py", line 1348, in do_open
    h.request(req.get_method(), req.selector, req.data, headers,
  File "/usr/lib/python3.10/http/client.py", line 1282, in request
    self._send_request(method, url, body, headers, encode_chunked)
  File "/usr/lib/python3.10/http/client.py", line 1328, in _send_request
    self.endheaders(body, encode_chunked=encode_chunked)
  File "/usr/lib/python3.10/http/client.py", line 1277, in endheaders
    self._send_output(message_body, encode_chunked=encode_chunked)
  File "/usr/lib/python3.10/http/client.py", line 1037, in _send_output
    self.send(msg)
  File "/usr/lib/python3.10/http/client.py", line 975, in send
    self.connect()
  File "/usr/lib/python3.10/http/client.py", line 1447, in connect
    super().connect()
  File "/usr/lib/python3.10/http/client.py", line 941, in connect
    self.sock = self._create_connection(
  File "/usr/lib/python3.10/socket.py", line 824, in create_connection
    for res in getaddrinfo(host, port, 0, SOCK_STREAM):
  File "/usr/lib/python3.10/socket.py", line 955, in getaddrinfo
    for res in _socket.getaddrinfo(host, port, family, type, proto, flags):
socket.gaierror: [Errno -3] Temporary failure in name resolution

During handling of the above exception, another exception occurred:

Traceback (most recent call last):
  File "/usr/bin/bpytop", line 5029, in _checker
    with urllib.request.urlopen("https://github.com/aristocratos/bpytop/raw/master/bpytop.py", timeout=5) as source: # type: ignore
  File "/usr/lib/python3.10/urllib/request.py", line 216, in urlopen
    return opener.open(url, data, timeout)
  File "/usr/lib/python3.10/urllib/request.py", line 519, in open
    response = self._open(req, data)
  File "/usr/lib/python3.10/urllib/request.py", line 536, in _open
    result = self._call_chain(self.handle_open, protocol, protocol +
  File "/usr/lib/python3.10/urllib/request.py", line 496, in _call_chain
    result = func(*args)
  File "/usr/lib/python3.10/urllib/request.py", line 1391, in https_open
    return self.do_open(http.client.HTTPSConnection, req,
  File "/usr/lib/python3.10/urllib/request.py", line 1351, in do_open
    raise URLError(err)
urllib.error.URLError: <urlopen error [Errno -3] Temporary failure in name resolution>
28/11/22 (11:04:27) | ERROR: <urlopen error [Errno -3] Temporary failure in name resolution>
Traceback (most recent call last):
  File "/usr/lib/python3.10/urllib/request.py", line 1348, in do_open
    h.request(req.get_method(), req.selector, req.data, headers,
  File "/usr/lib/python3.10/http/client.py", line 1282, in request
    self._send_request(method, url, body, headers, encode_chunked)
  File "/usr/lib/python3.10/http/client.py", line 1328, in _send_request
    self.endheaders(body, encode_chunked=encode_chunked)
  File "/usr/lib/python3.10/http/client.py", line 1277, in endheaders
    self._send_output(message_body, encode_chunked=encode_chunked)
  File "/usr/lib/python3.10/http/client.py", line 1037, in _send_output
    self.send(msg)
  File "/usr/lib/python3.10/http/client.py", line 975, in send
    self.connect()
  File "/usr/lib/python3.10/http/client.py", line 1447, in connect
    super().connect()
  File "/usr/lib/python3.10/http/client.py", line 941, in connect
    self.sock = self._create_connection(
  File "/usr/lib/python3.10/socket.py", line 824, in create_connection
    for res in getaddrinfo(host, port, 0, SOCK_STREAM):
  File "/usr/lib/python3.10/socket.py", line 955, in getaddrinfo
    for res in _socket.getaddrinfo(host, port, family, type, proto, flags):
socket.gaierror: [Errno -3] Temporary failure in name resolution

During handling of the above exception, another exception occurred:

Traceback (most recent call last):
  File "/usr/bin/bpytop", line 5029, in _checker
    with urllib.request.urlopen("https://github.com/aristocratos/bpytop/raw/master/bpytop.py", timeout=5) as source: # type: ignore
  File "/usr/lib/python3.10/urllib/request.py", line 216, in urlopen
    return opener.open(url, data, timeout)
  File "/usr/lib/python3.10/urllib/request.py", line 519, in open
    response = self._open(req, data)
  File "/usr/lib/python3.10/urllib/request.py", line 536, in _open
    result = self._call_chain(self.handle_open, protocol, protocol +
  File "/usr/lib/python3.10/urllib/request.py", line 496, in _call_chain
    result = func(*args)
  File "/usr/lib/python3.10/urllib/request.py", line 1391, in https_open
    return self.do_open(http.client.HTTPSConnection, req,
  File "/usr/lib/python3.10/urllib/request.py", line 1351, in do_open
    raise URLError(err)
urllib.error.URLError: <urlopen error [Errno -3] Temporary failure in name resolution>
29/11/22 (15:52:43) | ERROR: <urlopen error [Errno -3] Temporary failure in name resolution>
Traceback (most recent call last):
  File "/usr/lib/python3.10/urllib/request.py", line 1348, in do_open
    h.request(req.get_method(), req.selector, req.data, headers,
  File "/usr/lib/python3.10/http/client.py", line 1282, in request
    self._send_request(method, url, body, headers, encode_chunked)
  File "/usr/lib/python3.10/http/client.py", line 1328, in _send_request
    self.endheaders(body, encode_chunked=encode_chunked)
  File "/usr/lib/python3.10/http/client.py", line 1277, in endheaders
    self._send_output(message_body, encode_chunked=encode_chunked)
  File "/usr/lib/python3.10/http/client.py", line 1037, in _send_output
    self.send(msg)
  File "/usr/lib/python3.10/http/client.py", line 975, in send
    self.connect()
  File "/usr/lib/python3.10/http/client.py", line 1447, in connect
    super().connect()
  File "/usr/lib/python3.10/http/client.py", line 941, in connect
    self.sock = self._create_connection(
  File "/usr/lib/python3.10/socket.py", line 824, in create_connection
    for res in getaddrinfo(host, port, 0, SOCK_STREAM):
  File "/usr/lib/python3.10/socket.py", line 955, in getaddrinfo
    for res in _socket.getaddrinfo(host, port, family, type, proto, flags):
socket.gaierror: [Errno -3] Temporary failure in name resolution

During handling of the above exception, another exception occurred:

Traceback (most recent call last):
  File "/usr/bin/bpytop", line 5029, in _checker
    with urllib.request.urlopen("https://github.com/aristocratos/bpytop/raw/master/bpytop.py", timeout=5) as source: # type: ignore
  File "/usr/lib/python3.10/urllib/request.py", line 216, in urlopen
    return opener.open(url, data, timeout)
  File "/usr/lib/python3.10/urllib/request.py", line 519, in open
    response = self._open(req, data)
  File "/usr/lib/python3.10/urllib/request.py", line 536, in _open
    result = self._call_chain(self.handle_open, protocol, protocol +
  File "/usr/lib/python3.10/urllib/request.py", line 496, in _call_chain
    result = func(*args)
  File "/usr/lib/python3.10/urllib/request.py", line 1391, in https_open
    return self.do_open(http.client.HTTPSConnection, req,
  File "/usr/lib/python3.10/urllib/request.py", line 1351, in do_open
    raise URLError(err)
urllib.error.URLError: <urlopen error [Errno -3] Temporary failure in name resolution>
29/11/22 (15:53:47) | ERROR: <urlopen error [Errno -3] Temporary failure in name resolution>
Traceback (most recent call last):
  File "/usr/lib/python3.10/urllib/request.py", line 1348, in do_open
    h.request(req.get_method(), req.selector, req.data, headers,
  File "/usr/lib/python3.10/http/client.py", line 1282, in request
    self._send_request(method, url, body, headers, encode_chunked)
  File "/usr/lib/python3.10/http/client.py", line 1328, in _send_request
    self.endheaders(body, encode_chunked=encode_chunked)
  File "/usr/lib/python3.10/http/client.py", line 1277, in endheaders
    self._send_output(message_body, encode_chunked=encode_chunked)
  File "/usr/lib/python3.10/http/client.py", line 1037, in _send_output
    self.send(msg)
  File "/usr/lib/python3.10/http/client.py", line 975, in send
    self.connect()
  File "/usr/lib/python3.10/http/client.py", line 1447, in connect
    super().connect()
  File "/usr/lib/python3.10/http/client.py", line 941, in connect
    self.sock = self._create_connection(
  File "/usr/lib/python3.10/socket.py", line 824, in create_connection
    for res in getaddrinfo(host, port, 0, SOCK_STREAM):
  File "/usr/lib/python3.10/socket.py", line 955, in getaddrinfo
    for res in _socket.getaddrinfo(host, port, family, type, proto, flags):
socket.gaierror: [Errno -3] Temporary failure in name resolution

During handling of the above exception, another exception occurred:

Traceback (most recent call last):
  File "/usr/bin/bpytop", line 5029, in _checker
    with urllib.request.urlopen("https://github.com/aristocratos/bpytop/raw/master/bpytop.py", timeout=5) as source: # type: ignore
  File "/usr/lib/python3.10/urllib/request.py", line 216, in urlopen
    return opener.open(url, data, timeout)
  File "/usr/lib/python3.10/urllib/request.py", line 519, in open
    response = self._open(req, data)
  File "/usr/lib/python3.10/urllib/request.py", line 536, in _open
    result = self._call_chain(self.handle_open, protocol, protocol +
  File "/usr/lib/python3.10/urllib/request.py", line 496, in _call_chain
    result = func(*args)
  File "/usr/lib/python3.10/urllib/request.py", line 1391, in https_open
    return self.do_open(http.client.HTTPSConnection, req,
  File "/usr/lib/python3.10/urllib/request.py", line 1351, in do_open
    raise URLError(err)
urllib.error.URLError: <urlopen error [Errno -3] Temporary failure in name resolution>
02/12/22 (17:42:20) | ERROR: <urlopen error timed out>
Traceback (most recent call last):
  File "/usr/lib/python3.10/urllib/request.py", line 1348, in do_open
    h.request(req.get_method(), req.selector, req.data, headers,
  File "/usr/lib/python3.10/http/client.py", line 1282, in request
    self._send_request(method, url, body, headers, encode_chunked)
  File "/usr/lib/python3.10/http/client.py", line 1328, in _send_request
    self.endheaders(body, encode_chunked=encode_chunked)
  File "/usr/lib/python3.10/http/client.py", line 1277, in endheaders
    self._send_output(message_body, encode_chunked=encode_chunked)
  File "/usr/lib/python3.10/http/client.py", line 1037, in _send_output
    self.send(msg)
  File "/usr/lib/python3.10/http/client.py", line 975, in send
    self.connect()
  File "/usr/lib/python3.10/http/client.py", line 1447, in connect
    super().connect()
  File "/usr/lib/python3.10/http/client.py", line 941, in connect
    self.sock = self._create_connection(
  File "/usr/lib/python3.10/socket.py", line 845, in create_connection
    raise err
  File "/usr/lib/python3.10/socket.py", line 833, in create_connection
    sock.connect(sa)
TimeoutError: timed out

During handling of the above exception, another exception occurred:

Traceback (most recent call last):
  File "/usr/bin/bpytop", line 5029, in _checker
    with urllib.request.urlopen("https://github.com/aristocratos/bpytop/raw/master/bpytop.py", timeout=5) as source: # type: ignore
  File "/usr/lib/python3.10/urllib/request.py", line 216, in urlopen
    return opener.open(url, data, timeout)
  File "/usr/lib/python3.10/urllib/request.py", line 519, in open
    response = self._open(req, data)
  File "/usr/lib/python3.10/urllib/request.py", line 536, in _open
    result = self._call_chain(self.handle_open, protocol, protocol +
  File "/usr/lib/python3.10/urllib/request.py", line 496, in _call_chain
    result = func(*args)
  File "/usr/lib/python3.10/urllib/request.py", line 1391, in https_open
    return self.do_open(http.client.HTTPSConnection, req,
  File "/usr/lib/python3.10/urllib/request.py", line 1351, in do_open
    raise URLError(err)
urllib.error.URLError: <urlopen error timed out>
21/05/23 (12:52:16) | ERROR: <urlopen error [Errno -3] Temporary failure in name resolution>
Traceback (most recent call last):
  File "/usr/lib/python3.11/urllib/request.py", line 1348, in do_open
    h.request(req.get_method(), req.selector, req.data, headers,
  File "/usr/lib/python3.11/http/client.py", line 1283, in request
    self._send_request(method, url, body, headers, encode_chunked)
  File "/usr/lib/python3.11/http/client.py", line 1329, in _send_request
    self.endheaders(body, encode_chunked=encode_chunked)
  File "/usr/lib/python3.11/http/client.py", line 1278, in endheaders
    self._send_output(message_body, encode_chunked=encode_chunked)
  File "/usr/lib/python3.11/http/client.py", line 1038, in _send_output
    self.send(msg)
  File "/usr/lib/python3.11/http/client.py", line 976, in send
    self.connect()
  File "/usr/lib/python3.11/http/client.py", line 1448, in connect
    super().connect()
  File "/usr/lib/python3.11/http/client.py", line 942, in connect
    self.sock = self._create_connection(
                ^^^^^^^^^^^^^^^^^^^^^^^^
  File "/usr/lib/python3.11/socket.py", line 827, in create_connection
    for res in getaddrinfo(host, port, 0, SOCK_STREAM):
               ^^^^^^^^^^^^^^^^^^^^^^^^^^^^^^^^^^^^^^^
  File "/usr/lib/python3.11/socket.py", line 962, in getaddrinfo
    for res in _socket.getaddrinfo(host, port, family, type, proto, flags):
               ^^^^^^^^^^^^^^^^^^^^^^^^^^^^^^^^^^^^^^^^^^^^^^^^^^^^^^^^^^^
socket.gaierror: [Errno -3] Temporary failure in name resolution

During handling of the above exception, another exception occurred:

Traceback (most recent call last):
  File "/usr/bin/bpytop", line 5029, in _checker
    with urllib.request.urlopen("https://github.com/aristocratos/bpytop/raw/master/bpytop.py", timeout=5) as source: # type: ignore
         ^^^^^^^^^^^^^^^^^^^^^^^^^^^^^^^^^^^^^^^^^^^^^^^^^^^^^^^^^^^^^^^^^^^^^^^^^^^^^^^^^^^^^^^^^^^^^^^^
  File "/usr/lib/python3.11/urllib/request.py", line 216, in urlopen
    return opener.open(url, data, timeout)
           ^^^^^^^^^^^^^^^^^^^^^^^^^^^^^^^
  File "/usr/lib/python3.11/urllib/request.py", line 519, in open
    response = self._open(req, data)
               ^^^^^^^^^^^^^^^^^^^^^
  File "/usr/lib/python3.11/urllib/request.py", line 536, in _open
    result = self._call_chain(self.handle_open, protocol, protocol +
             ^^^^^^^^^^^^^^^^^^^^^^^^^^^^^^^^^^^^^^^^^^^^^^^^^^^^^^^
  File "/usr/lib/python3.11/urllib/request.py", line 496, in _call_chain
    result = func(*args)
             ^^^^^^^^^^^
  File "/usr/lib/python3.11/urllib/request.py", line 1391, in https_open
    return self.do_open(http.client.HTTPSConnection, req,
           ^^^^^^^^^^^^^^^^^^^^^^^^^^^^^^^^^^^^^^^^^^^^^^
  File "/usr/lib/python3.11/urllib/request.py", line 1351, in do_open
    raise URLError(err)
urllib.error.URLError: <urlopen error [Errno -3] Temporary failure in name resolution>
12/06/23 (11:07:57) | ERROR: <urlopen error [SSL: CERTIFICATE_VERIFY_FAILED] certificate verify failed: Hostname mismatch, certificate is not valid for 'github.com'. (_ssl.c:1002)>
Traceback (most recent call last):
  File "/usr/lib/python3.11/urllib/request.py", line 1348, in do_open
    h.request(req.get_method(), req.selector, req.data, headers,
  File "/usr/lib/python3.11/http/client.py", line 1283, in request
    self._send_request(method, url, body, headers, encode_chunked)
  File "/usr/lib/python3.11/http/client.py", line 1329, in _send_request
    self.endheaders(body, encode_chunked=encode_chunked)
  File "/usr/lib/python3.11/http/client.py", line 1278, in endheaders
    self._send_output(message_body, encode_chunked=encode_chunked)
  File "/usr/lib/python3.11/http/client.py", line 1038, in _send_output
    self.send(msg)
  File "/usr/lib/python3.11/http/client.py", line 976, in send
    self.connect()
  File "/usr/lib/python3.11/http/client.py", line 1455, in connect
    self.sock = self._context.wrap_socket(self.sock,
                ^^^^^^^^^^^^^^^^^^^^^^^^^^^^^^^^^^^^
  File "/usr/lib/python3.11/ssl.py", line 517, in wrap_socket
    return self.sslsocket_class._create(
           ^^^^^^^^^^^^^^^^^^^^^^^^^^^^^
  File "/usr/lib/python3.11/ssl.py", line 1075, in _create
    self.do_handshake()
  File "/usr/lib/python3.11/ssl.py", line 1346, in do_handshake
    self._sslobj.do_handshake()
ssl.SSLCertVerificationError: [SSL: CERTIFICATE_VERIFY_FAILED] certificate verify failed: Hostname mismatch, certificate is not valid for 'github.com'. (_ssl.c:1002)

During handling of the above exception, another exception occurred:

Traceback (most recent call last):
  File "/usr/bin/bpytop", line 5029, in _checker
    with urllib.request.urlopen("https://github.com/aristocratos/bpytop/raw/master/bpytop.py", timeout=5) as source: # type: ignore
         ^^^^^^^^^^^^^^^^^^^^^^^^^^^^^^^^^^^^^^^^^^^^^^^^^^^^^^^^^^^^^^^^^^^^^^^^^^^^^^^^^^^^^^^^^^^^^^^^
  File "/usr/lib/python3.11/urllib/request.py", line 216, in urlopen
    return opener.open(url, data, timeout)
           ^^^^^^^^^^^^^^^^^^^^^^^^^^^^^^^
  File "/usr/lib/python3.11/urllib/request.py", line 519, in open
    response = self._open(req, data)
               ^^^^^^^^^^^^^^^^^^^^^
  File "/usr/lib/python3.11/urllib/request.py", line 536, in _open
    result = self._call_chain(self.handle_open, protocol, protocol +
             ^^^^^^^^^^^^^^^^^^^^^^^^^^^^^^^^^^^^^^^^^^^^^^^^^^^^^^^
  File "/usr/lib/python3.11/urllib/request.py", line 496, in _call_chain
    result = func(*args)
             ^^^^^^^^^^^
  File "/usr/lib/python3.11/urllib/request.py", line 1391, in https_open
    return self.do_open(http.client.HTTPSConnection, req,
           ^^^^^^^^^^^^^^^^^^^^^^^^^^^^^^^^^^^^^^^^^^^^^^
  File "/usr/lib/python3.11/urllib/request.py", line 1351, in do_open
    raise URLError(err)
urllib.error.URLError: <urlopen error [SSL: CERTIFICATE_VERIFY_FAILED] certificate verify failed: Hostname mismatch, certificate is not valid for 'github.com'. (_ssl.c:1002)>
13/11/23 (12:29:45) | ERROR: <urlopen error [Errno -3] Temporary failure in name resolution>
Traceback (most recent call last):
  File "/usr/lib/python3.11/urllib/request.py", line 1348, in do_open
    h.request(req.get_method(), req.selector, req.data, headers,
  File "/usr/lib/python3.11/http/client.py", line 1286, in request
    self._send_request(method, url, body, headers, encode_chunked)
  File "/usr/lib/python3.11/http/client.py", line 1332, in _send_request
    self.endheaders(body, encode_chunked=encode_chunked)
  File "/usr/lib/python3.11/http/client.py", line 1281, in endheaders
    self._send_output(message_body, encode_chunked=encode_chunked)
  File "/usr/lib/python3.11/http/client.py", line 1041, in _send_output
    self.send(msg)
  File "/usr/lib/python3.11/http/client.py", line 979, in send
    self.connect()
  File "/usr/lib/python3.11/http/client.py", line 1451, in connect
    super().connect()
  File "/usr/lib/python3.11/http/client.py", line 945, in connect
    self.sock = self._create_connection(
                ^^^^^^^^^^^^^^^^^^^^^^^^
  File "/usr/lib/python3.11/socket.py", line 827, in create_connection
    for res in getaddrinfo(host, port, 0, SOCK_STREAM):
               ^^^^^^^^^^^^^^^^^^^^^^^^^^^^^^^^^^^^^^^
  File "/usr/lib/python3.11/socket.py", line 962, in getaddrinfo
    for res in _socket.getaddrinfo(host, port, family, type, proto, flags):
               ^^^^^^^^^^^^^^^^^^^^^^^^^^^^^^^^^^^^^^^^^^^^^^^^^^^^^^^^^^^
socket.gaierror: [Errno -3] Temporary failure in name resolution

During handling of the above exception, another exception occurred:

Traceback (most recent call last):
  File "/usr/bin/bpytop", line 5029, in _checker
    with urllib.request.urlopen("https://github.com/aristocratos/bpytop/raw/master/bpytop.py", timeout=5) as source: # type: ignore
         ^^^^^^^^^^^^^^^^^^^^^^^^^^^^^^^^^^^^^^^^^^^^^^^^^^^^^^^^^^^^^^^^^^^^^^^^^^^^^^^^^^^^^^^^^^^^^^^^
  File "/usr/lib/python3.11/urllib/request.py", line 216, in urlopen
    return opener.open(url, data, timeout)
           ^^^^^^^^^^^^^^^^^^^^^^^^^^^^^^^
  File "/usr/lib/python3.11/urllib/request.py", line 519, in open
    response = self._open(req, data)
               ^^^^^^^^^^^^^^^^^^^^^
  File "/usr/lib/python3.11/urllib/request.py", line 536, in _open
    result = self._call_chain(self.handle_open, protocol, protocol +
             ^^^^^^^^^^^^^^^^^^^^^^^^^^^^^^^^^^^^^^^^^^^^^^^^^^^^^^^
  File "/usr/lib/python3.11/urllib/request.py", line 496, in _call_chain
    result = func(*args)
             ^^^^^^^^^^^
  File "/usr/lib/python3.11/urllib/request.py", line 1391, in https_open
    return self.do_open(http.client.HTTPSConnection, req,
           ^^^^^^^^^^^^^^^^^^^^^^^^^^^^^^^^^^^^^^^^^^^^^^
  File "/usr/lib/python3.11/urllib/request.py", line 1351, in do_open
    raise URLError(err)
urllib.error.URLError: <urlopen error [Errno -3] Temporary failure in name resolution>
23/04/24 (23:18:30) | ERROR: Remote end closed connection without response
Traceback (most recent call last):
  File "/usr/bin/bpytop", line 5029, in _checker
    with urllib.request.urlopen("https://github.com/aristocratos/bpytop/raw/master/bpytop.py", timeout=5) as source: # type: ignore
         ^^^^^^^^^^^^^^^^^^^^^^^^^^^^^^^^^^^^^^^^^^^^^^^^^^^^^^^^^^^^^^^^^^^^^^^^^^^^^^^^^^^^^^^^^^^^^^^^
  File "/usr/lib/python3.11/urllib/request.py", line 216, in urlopen
    return opener.open(url, data, timeout)
           ^^^^^^^^^^^^^^^^^^^^^^^^^^^^^^^
  File "/usr/lib/python3.11/urllib/request.py", line 525, in open
    response = meth(req, response)
               ^^^^^^^^^^^^^^^^^^^
  File "/usr/lib/python3.11/urllib/request.py", line 634, in http_response
    response = self.parent.error(
               ^^^^^^^^^^^^^^^^^^
  File "/usr/lib/python3.11/urllib/request.py", line 557, in error
    result = self._call_chain(*args)
             ^^^^^^^^^^^^^^^^^^^^^^^
  File "/usr/lib/python3.11/urllib/request.py", line 496, in _call_chain
    result = func(*args)
             ^^^^^^^^^^^
  File "/usr/lib/python3.11/urllib/request.py", line 749, in http_error_302
    return self.parent.open(new, timeout=req.timeout)
           ^^^^^^^^^^^^^^^^^^^^^^^^^^^^^^^^^^^^^^^^^^
  File "/usr/lib/python3.11/urllib/request.py", line 519, in open
    response = self._open(req, data)
               ^^^^^^^^^^^^^^^^^^^^^
  File "/usr/lib/python3.11/urllib/request.py", line 536, in _open
    result = self._call_chain(self.handle_open, protocol, protocol +
             ^^^^^^^^^^^^^^^^^^^^^^^^^^^^^^^^^^^^^^^^^^^^^^^^^^^^^^^
  File "/usr/lib/python3.11/urllib/request.py", line 496, in _call_chain
    result = func(*args)
             ^^^^^^^^^^^
  File "/usr/lib/python3.11/urllib/request.py", line 1391, in https_open
    return self.do_open(http.client.HTTPSConnection, req,
           ^^^^^^^^^^^^^^^^^^^^^^^^^^^^^^^^^^^^^^^^^^^^^^
  File "/usr/lib/python3.11/urllib/request.py", line 1352, in do_open
    r = h.getresponse()
        ^^^^^^^^^^^^^^^
  File "/usr/lib/python3.11/http/client.py", line 1390, in getresponse
    response.begin()
  File "/usr/lib/python3.11/http/client.py", line 325, in begin
    version, status, reason = self._read_status()
                              ^^^^^^^^^^^^^^^^^^^
  File "/usr/lib/python3.11/http/client.py", line 294, in _read_status
    raise RemoteDisconnected("Remote end closed connection without"
http.client.RemoteDisconnected: Remote end closed connection without response
19/07/24 (06:32:53) | ERROR: <urlopen error [Errno -3] Temporary failure in name resolution>
Traceback (most recent call last):
  File "/usr/lib/python3.12/urllib/request.py", line 1344, in do_open
    h.request(req.get_method(), req.selector, req.data, headers,
  File "/usr/lib/python3.12/http/client.py", line 1336, in request
    self._send_request(method, url, body, headers, encode_chunked)
  File "/usr/lib/python3.12/http/client.py", line 1382, in _send_request
    self.endheaders(body, encode_chunked=encode_chunked)
  File "/usr/lib/python3.12/http/client.py", line 1331, in endheaders
    self._send_output(message_body, encode_chunked=encode_chunked)
  File "/usr/lib/python3.12/http/client.py", line 1091, in _send_output
    self.send(msg)
  File "/usr/lib/python3.12/http/client.py", line 1035, in send
    self.connect()
  File "/usr/lib/python3.12/http/client.py", line 1470, in connect
    super().connect()
  File "/usr/lib/python3.12/http/client.py", line 1001, in connect
    self.sock = self._create_connection(
                ^^^^^^^^^^^^^^^^^^^^^^^^
  File "/usr/lib/python3.12/socket.py", line 829, in create_connection
    for res in getaddrinfo(host, port, 0, SOCK_STREAM):
               ^^^^^^^^^^^^^^^^^^^^^^^^^^^^^^^^^^^^^^^
  File "/usr/lib/python3.12/socket.py", line 964, in getaddrinfo
    for res in _socket.getaddrinfo(host, port, family, type, proto, flags):
               ^^^^^^^^^^^^^^^^^^^^^^^^^^^^^^^^^^^^^^^^^^^^^^^^^^^^^^^^^^^
socket.gaierror: [Errno -3] Temporary failure in name resolution

During handling of the above exception, another exception occurred:

Traceback (most recent call last):
  File "/usr/bin/bpytop", line 5029, in _checker
    with urllib.request.urlopen("https://github.com/aristocratos/bpytop/raw/master/bpytop.py", timeout=5) as source: # type: ignore
         ^^^^^^^^^^^^^^^^^^^^^^^^^^^^^^^^^^^^^^^^^^^^^^^^^^^^^^^^^^^^^^^^^^^^^^^^^^^^^^^^^^^^^^^^^^^^^^^^
  File "/usr/lib/python3.12/urllib/request.py", line 215, in urlopen
    return opener.open(url, data, timeout)
           ^^^^^^^^^^^^^^^^^^^^^^^^^^^^^^^
  File "/usr/lib/python3.12/urllib/request.py", line 515, in open
    response = self._open(req, data)
               ^^^^^^^^^^^^^^^^^^^^^
  File "/usr/lib/python3.12/urllib/request.py", line 532, in _open
    result = self._call_chain(self.handle_open, protocol, protocol +
             ^^^^^^^^^^^^^^^^^^^^^^^^^^^^^^^^^^^^^^^^^^^^^^^^^^^^^^^
  File "/usr/lib/python3.12/urllib/request.py", line 492, in _call_chain
    result = func(*args)
             ^^^^^^^^^^^
  File "/usr/lib/python3.12/urllib/request.py", line 1392, in https_open
    return self.do_open(http.client.HTTPSConnection, req,
           ^^^^^^^^^^^^^^^^^^^^^^^^^^^^^^^^^^^^^^^^^^^^^^
  File "/usr/lib/python3.12/urllib/request.py", line 1347, in do_open
    raise URLError(err)
urllib.error.URLError: <urlopen error [Errno -3] Temporary failure in name resolution>
19/07/24 (06:34:39) | ERROR: <urlopen error [Errno -3] Temporary failure in name resolution>
Traceback (most recent call last):
  File "/usr/lib/python3.12/urllib/request.py", line 1344, in do_open
    h.request(req.get_method(), req.selector, req.data, headers,
  File "/usr/lib/python3.12/http/client.py", line 1336, in request
    self._send_request(method, url, body, headers, encode_chunked)
  File "/usr/lib/python3.12/http/client.py", line 1382, in _send_request
    self.endheaders(body, encode_chunked=encode_chunked)
  File "/usr/lib/python3.12/http/client.py", line 1331, in endheaders
    self._send_output(message_body, encode_chunked=encode_chunked)
  File "/usr/lib/python3.12/http/client.py", line 1091, in _send_output
    self.send(msg)
  File "/usr/lib/python3.12/http/client.py", line 1035, in send
    self.connect()
  File "/usr/lib/python3.12/http/client.py", line 1470, in connect
    super().connect()
  File "/usr/lib/python3.12/http/client.py", line 1001, in connect
    self.sock = self._create_connection(
                ^^^^^^^^^^^^^^^^^^^^^^^^
  File "/usr/lib/python3.12/socket.py", line 829, in create_connection
    for res in getaddrinfo(host, port, 0, SOCK_STREAM):
               ^^^^^^^^^^^^^^^^^^^^^^^^^^^^^^^^^^^^^^^
  File "/usr/lib/python3.12/socket.py", line 964, in getaddrinfo
    for res in _socket.getaddrinfo(host, port, family, type, proto, flags):
               ^^^^^^^^^^^^^^^^^^^^^^^^^^^^^^^^^^^^^^^^^^^^^^^^^^^^^^^^^^^
socket.gaierror: [Errno -3] Temporary failure in name resolution

During handling of the above exception, another exception occurred:

Traceback (most recent call last):
  File "/usr/bin/bpytop", line 5029, in _checker
    with urllib.request.urlopen("https://github.com/aristocratos/bpytop/raw/master/bpytop.py", timeout=5) as source: # type: ignore
         ^^^^^^^^^^^^^^^^^^^^^^^^^^^^^^^^^^^^^^^^^^^^^^^^^^^^^^^^^^^^^^^^^^^^^^^^^^^^^^^^^^^^^^^^^^^^^^^^
  File "/usr/lib/python3.12/urllib/request.py", line 215, in urlopen
    return opener.open(url, data, timeout)
           ^^^^^^^^^^^^^^^^^^^^^^^^^^^^^^^
  File "/usr/lib/python3.12/urllib/request.py", line 515, in open
    response = self._open(req, data)
               ^^^^^^^^^^^^^^^^^^^^^
  File "/usr/lib/python3.12/urllib/request.py", line 532, in _open
    result = self._call_chain(self.handle_open, protocol, protocol +
             ^^^^^^^^^^^^^^^^^^^^^^^^^^^^^^^^^^^^^^^^^^^^^^^^^^^^^^^
  File "/usr/lib/python3.12/urllib/request.py", line 492, in _call_chain
    result = func(*args)
             ^^^^^^^^^^^
  File "/usr/lib/python3.12/urllib/request.py", line 1392, in https_open
    return self.do_open(http.client.HTTPSConnection, req,
           ^^^^^^^^^^^^^^^^^^^^^^^^^^^^^^^^^^^^^^^^^^^^^^
  File "/usr/lib/python3.12/urllib/request.py", line 1347, in do_open
    raise URLError(err)
urllib.error.URLError: <urlopen error [Errno -3] Temporary failure in name resolution>
19/07/24 (06:38:11) | ERROR: <urlopen error [Errno -3] Temporary failure in name resolution>
Traceback (most recent call last):
  File "/usr/lib/python3.12/urllib/request.py", line 1344, in do_open
    h.request(req.get_method(), req.selector, req.data, headers,
  File "/usr/lib/python3.12/http/client.py", line 1336, in request
    self._send_request(method, url, body, headers, encode_chunked)
  File "/usr/lib/python3.12/http/client.py", line 1382, in _send_request
    self.endheaders(body, encode_chunked=encode_chunked)
  File "/usr/lib/python3.12/http/client.py", line 1331, in endheaders
    self._send_output(message_body, encode_chunked=encode_chunked)
  File "/usr/lib/python3.12/http/client.py", line 1091, in _send_output
    self.send(msg)
  File "/usr/lib/python3.12/http/client.py", line 1035, in send
    self.connect()
  File "/usr/lib/python3.12/http/client.py", line 1470, in connect
    super().connect()
  File "/usr/lib/python3.12/http/client.py", line 1001, in connect
    self.sock = self._create_connection(
                ^^^^^^^^^^^^^^^^^^^^^^^^
  File "/usr/lib/python3.12/socket.py", line 829, in create_connection
    for res in getaddrinfo(host, port, 0, SOCK_STREAM):
               ^^^^^^^^^^^^^^^^^^^^^^^^^^^^^^^^^^^^^^^
  File "/usr/lib/python3.12/socket.py", line 964, in getaddrinfo
    for res in _socket.getaddrinfo(host, port, family, type, proto, flags):
               ^^^^^^^^^^^^^^^^^^^^^^^^^^^^^^^^^^^^^^^^^^^^^^^^^^^^^^^^^^^
socket.gaierror: [Errno -3] Temporary failure in name resolution

During handling of the above exception, another exception occurred:

Traceback (most recent call last):
  File "/usr/bin/bpytop", line 5029, in _checker
    with urllib.request.urlopen("https://github.com/aristocratos/bpytop/raw/master/bpytop.py", timeout=5) as source: # type: ignore
         ^^^^^^^^^^^^^^^^^^^^^^^^^^^^^^^^^^^^^^^^^^^^^^^^^^^^^^^^^^^^^^^^^^^^^^^^^^^^^^^^^^^^^^^^^^^^^^^^
  File "/usr/lib/python3.12/urllib/request.py", line 215, in urlopen
    return opener.open(url, data, timeout)
           ^^^^^^^^^^^^^^^^^^^^^^^^^^^^^^^
  File "/usr/lib/python3.12/urllib/request.py", line 515, in open
    response = self._open(req, data)
               ^^^^^^^^^^^^^^^^^^^^^
  File "/usr/lib/python3.12/urllib/request.py", line 532, in _open
    result = self._call_chain(self.handle_open, protocol, protocol +
             ^^^^^^^^^^^^^^^^^^^^^^^^^^^^^^^^^^^^^^^^^^^^^^^^^^^^^^^
  File "/usr/lib/python3.12/urllib/request.py", line 492, in _call_chain
    result = func(*args)
             ^^^^^^^^^^^
  File "/usr/lib/python3.12/urllib/request.py", line 1392, in https_open
    return self.do_open(http.client.HTTPSConnection, req,
           ^^^^^^^^^^^^^^^^^^^^^^^^^^^^^^^^^^^^^^^^^^^^^^
  File "/usr/lib/python3.12/urllib/request.py", line 1347, in do_open
    raise URLError(err)
urllib.error.URLError: <urlopen error [Errno -3] Temporary failure in name resolution>
28/07/24 (08:15:56) | ERROR: Data collection thread failed with exception: min() iterable argument is empty
Traceback (most recent call last):
  File "/usr/bin/bpytop", line 2958, in _runner
    collector._collect()
  File "/usr/bin/bpytop", line 3726, in _collect
    cls._tree(sort_cmd=sort_cmd, reverse=reverse, proc_per_cpu=proc_per_cpu, search=search)
  File "/usr/bin/bpytop", line 3968, in _tree
    create_tree(min(tree), tree)
                ^^^^^^^^^
ValueError: min() iterable argument is empty
28/07/24 (08:15:56) | WARNING: Exiting with errorcode (1). Runtime 1 day, 9:53:05 

30/07/24 (07:38:45) | ERROR: Data collection thread failed with exception: min() iterable argument is empty
Traceback (most recent call last):
  File "/usr/bin/bpytop", line 2958, in _runner
    collector._collect()
  File "/usr/bin/bpytop", line 3726, in _collect
    cls._tree(sort_cmd=sort_cmd, reverse=reverse, proc_per_cpu=proc_per_cpu, search=search)
  File "/usr/bin/bpytop", line 3968, in _tree
    create_tree(min(tree), tree)
                ^^^^^^^^^
ValueError: min() iterable argument is empty
30/07/24 (07:38:45) | WARNING: Exiting with errorcode (1). Runtime 15:23:41 

08/08/24 (08:53:59) | ERROR: <urlopen error [Errno -3] Temporary failure in name resolution>
Traceback (most recent call last):
  File "/usr/lib/python3.12/urllib/request.py", line 1344, in do_open
    h.request(req.get_method(), req.selector, req.data, headers,
  File "/usr/lib/python3.12/http/client.py", line 1336, in request
    self._send_request(method, url, body, headers, encode_chunked)
  File "/usr/lib/python3.12/http/client.py", line 1382, in _send_request
    self.endheaders(body, encode_chunked=encode_chunked)
  File "/usr/lib/python3.12/http/client.py", line 1331, in endheaders
    self._send_output(message_body, encode_chunked=encode_chunked)
  File "/usr/lib/python3.12/http/client.py", line 1091, in _send_output
    self.send(msg)
  File "/usr/lib/python3.12/http/client.py", line 1035, in send
    self.connect()
  File "/usr/lib/python3.12/http/client.py", line 1470, in connect
    super().connect()
  File "/usr/lib/python3.12/http/client.py", line 1001, in connect
    self.sock = self._create_connection(
                ^^^^^^^^^^^^^^^^^^^^^^^^
  File "/usr/lib/python3.12/socket.py", line 829, in create_connection
    for res in getaddrinfo(host, port, 0, SOCK_STREAM):
               ^^^^^^^^^^^^^^^^^^^^^^^^^^^^^^^^^^^^^^^
  File "/usr/lib/python3.12/socket.py", line 964, in getaddrinfo
    for res in _socket.getaddrinfo(host, port, family, type, proto, flags):
               ^^^^^^^^^^^^^^^^^^^^^^^^^^^^^^^^^^^^^^^^^^^^^^^^^^^^^^^^^^^
socket.gaierror: [Errno -3] Temporary failure in name resolution

During handling of the above exception, another exception occurred:

Traceback (most recent call last):
  File "/usr/bin/bpytop", line 5029, in _checker
    with urllib.request.urlopen("https://github.com/aristocratos/bpytop/raw/master/bpytop.py", timeout=5) as source: # type: ignore
         ^^^^^^^^^^^^^^^^^^^^^^^^^^^^^^^^^^^^^^^^^^^^^^^^^^^^^^^^^^^^^^^^^^^^^^^^^^^^^^^^^^^^^^^^^^^^^^^^
  File "/usr/lib/python3.12/urllib/request.py", line 215, in urlopen
    return opener.open(url, data, timeout)
           ^^^^^^^^^^^^^^^^^^^^^^^^^^^^^^^
  File "/usr/lib/python3.12/urllib/request.py", line 515, in open
    response = self._open(req, data)
               ^^^^^^^^^^^^^^^^^^^^^
  File "/usr/lib/python3.12/urllib/request.py", line 532, in _open
    result = self._call_chain(self.handle_open, protocol, protocol +
             ^^^^^^^^^^^^^^^^^^^^^^^^^^^^^^^^^^^^^^^^^^^^^^^^^^^^^^^
  File "/usr/lib/python3.12/urllib/request.py", line 492, in _call_chain
    result = func(*args)
             ^^^^^^^^^^^
  File "/usr/lib/python3.12/urllib/request.py", line 1392, in https_open
    return self.do_open(http.client.HTTPSConnection, req,
           ^^^^^^^^^^^^^^^^^^^^^^^^^^^^^^^^^^^^^^^^^^^^^^
  File "/usr/lib/python3.12/urllib/request.py", line 1347, in do_open
    raise URLError(err)
urllib.error.URLError: <urlopen error [Errno -3] Temporary failure in name resolution>
08/08/24 (08:54:09) | ERROR: <urlopen error [Errno -3] Temporary failure in name resolution>
Traceback (most recent call last):
  File "/usr/lib/python3.12/urllib/request.py", line 1344, in do_open
    h.request(req.get_method(), req.selector, req.data, headers,
  File "/usr/lib/python3.12/http/client.py", line 1336, in request
    self._send_request(method, url, body, headers, encode_chunked)
  File "/usr/lib/python3.12/http/client.py", line 1382, in _send_request
    self.endheaders(body, encode_chunked=encode_chunked)
  File "/usr/lib/python3.12/http/client.py", line 1331, in endheaders
    self._send_output(message_body, encode_chunked=encode_chunked)
  File "/usr/lib/python3.12/http/client.py", line 1091, in _send_output
    self.send(msg)
  File "/usr/lib/python3.12/http/client.py", line 1035, in send
    self.connect()
  File "/usr/lib/python3.12/http/client.py", line 1470, in connect
    super().connect()
  File "/usr/lib/python3.12/http/client.py", line 1001, in connect
    self.sock = self._create_connection(
                ^^^^^^^^^^^^^^^^^^^^^^^^
  File "/usr/lib/python3.12/socket.py", line 829, in create_connection
    for res in getaddrinfo(host, port, 0, SOCK_STREAM):
               ^^^^^^^^^^^^^^^^^^^^^^^^^^^^^^^^^^^^^^^
  File "/usr/lib/python3.12/socket.py", line 964, in getaddrinfo
    for res in _socket.getaddrinfo(host, port, family, type, proto, flags):
               ^^^^^^^^^^^^^^^^^^^^^^^^^^^^^^^^^^^^^^^^^^^^^^^^^^^^^^^^^^^
socket.gaierror: [Errno -3] Temporary failure in name resolution

During handling of the above exception, another exception occurred:

Traceback (most recent call last):
  File "/usr/bin/bpytop", line 5029, in _checker
    with urllib.request.urlopen("https://github.com/aristocratos/bpytop/raw/master/bpytop.py", timeout=5) as source: # type: ignore
         ^^^^^^^^^^^^^^^^^^^^^^^^^^^^^^^^^^^^^^^^^^^^^^^^^^^^^^^^^^^^^^^^^^^^^^^^^^^^^^^^^^^^^^^^^^^^^^^^
  File "/usr/lib/python3.12/urllib/request.py", line 215, in urlopen
    return opener.open(url, data, timeout)
           ^^^^^^^^^^^^^^^^^^^^^^^^^^^^^^^
  File "/usr/lib/python3.12/urllib/request.py", line 515, in open
    response = self._open(req, data)
               ^^^^^^^^^^^^^^^^^^^^^
  File "/usr/lib/python3.12/urllib/request.py", line 532, in _open
    result = self._call_chain(self.handle_open, protocol, protocol +
             ^^^^^^^^^^^^^^^^^^^^^^^^^^^^^^^^^^^^^^^^^^^^^^^^^^^^^^^
  File "/usr/lib/python3.12/urllib/request.py", line 492, in _call_chain
    result = func(*args)
             ^^^^^^^^^^^
  File "/usr/lib/python3.12/urllib/request.py", line 1392, in https_open
    return self.do_open(http.client.HTTPSConnection, req,
           ^^^^^^^^^^^^^^^^^^^^^^^^^^^^^^^^^^^^^^^^^^^^^^
  File "/usr/lib/python3.12/urllib/request.py", line 1347, in do_open
    raise URLError(err)
urllib.error.URLError: <urlopen error [Errno -3] Temporary failure in name resolution>
11/08/24 (14:11:28) | ERROR: Data collection thread failed with exception: min() iterable argument is empty
Traceback (most recent call last):
  File "/usr/bin/bpytop", line 2958, in _runner
    collector._collect()
  File "/usr/bin/bpytop", line 3726, in _collect
    cls._tree(sort_cmd=sort_cmd, reverse=reverse, proc_per_cpu=proc_per_cpu, search=search)
  File "/usr/bin/bpytop", line 3968, in _tree
    create_tree(min(tree), tree)
                ^^^^^^^^^
ValueError: min() iterable argument is empty
11/08/24 (14:11:28) | WARNING: Exiting with errorcode (1). Runtime 12:14:32 

13/08/24 (10:15:28) | ERROR: Data collection thread failed with exception: min() iterable argument is empty
Traceback (most recent call last):
  File "/usr/bin/bpytop", line 2958, in _runner
    collector._collect()
  File "/usr/bin/bpytop", line 3726, in _collect
    cls._tree(sort_cmd=sort_cmd, reverse=reverse, proc_per_cpu=proc_per_cpu, search=search)
  File "/usr/bin/bpytop", line 3968, in _tree
    create_tree(min(tree), tree)
                ^^^^^^^^^
ValueError: min() iterable argument is empty
13/08/24 (10:15:29) | WARNING: Exiting with errorcode (1). Runtime 0:03:50 

21/08/24 (00:26:32) | ERROR: <urlopen error timed out>
Traceback (most recent call last):
  File "/usr/lib/python3.12/urllib/request.py", line 1344, in do_open
    h.request(req.get_method(), req.selector, req.data, headers,
  File "/usr/lib/python3.12/http/client.py", line 1336, in request
    self._send_request(method, url, body, headers, encode_chunked)
  File "/usr/lib/python3.12/http/client.py", line 1382, in _send_request
    self.endheaders(body, encode_chunked=encode_chunked)
  File "/usr/lib/python3.12/http/client.py", line 1331, in endheaders
    self._send_output(message_body, encode_chunked=encode_chunked)
  File "/usr/lib/python3.12/http/client.py", line 1091, in _send_output
    self.send(msg)
  File "/usr/lib/python3.12/http/client.py", line 1035, in send
    self.connect()
  File "/usr/lib/python3.12/http/client.py", line 1470, in connect
    super().connect()
  File "/usr/lib/python3.12/http/client.py", line 1001, in connect
    self.sock = self._create_connection(
                ^^^^^^^^^^^^^^^^^^^^^^^^
  File "/usr/lib/python3.12/socket.py", line 853, in create_connection
    raise exceptions[0]
  File "/usr/lib/python3.12/socket.py", line 838, in create_connection
    sock.connect(sa)
TimeoutError: timed out

During handling of the above exception, another exception occurred:

Traceback (most recent call last):
  File "/usr/bin/bpytop", line 5029, in _checker
    with urllib.request.urlopen("https://github.com/aristocratos/bpytop/raw/master/bpytop.py", timeout=5) as source: # type: ignore
         ^^^^^^^^^^^^^^^^^^^^^^^^^^^^^^^^^^^^^^^^^^^^^^^^^^^^^^^^^^^^^^^^^^^^^^^^^^^^^^^^^^^^^^^^^^^^^^^^
  File "/usr/lib/python3.12/urllib/request.py", line 215, in urlopen
    return opener.open(url, data, timeout)
           ^^^^^^^^^^^^^^^^^^^^^^^^^^^^^^^
  File "/usr/lib/python3.12/urllib/request.py", line 515, in open
    response = self._open(req, data)
               ^^^^^^^^^^^^^^^^^^^^^
  File "/usr/lib/python3.12/urllib/request.py", line 532, in _open
    result = self._call_chain(self.handle_open, protocol, protocol +
             ^^^^^^^^^^^^^^^^^^^^^^^^^^^^^^^^^^^^^^^^^^^^^^^^^^^^^^^
  File "/usr/lib/python3.12/urllib/request.py", line 492, in _call_chain
    result = func(*args)
             ^^^^^^^^^^^
  File "/usr/lib/python3.12/urllib/request.py", line 1392, in https_open
    return self.do_open(http.client.HTTPSConnection, req,
           ^^^^^^^^^^^^^^^^^^^^^^^^^^^^^^^^^^^^^^^^^^^^^^
  File "/usr/lib/python3.12/urllib/request.py", line 1347, in do_open
    raise URLError(err)
urllib.error.URLError: <urlopen error timed out>
23/08/24 (13:06:28) | ERROR: Data collection thread failed with exception: min() iterable argument is empty
Traceback (most recent call last):
  File "/usr/bin/bpytop", line 2958, in _runner
    collector._collect()
  File "/usr/bin/bpytop", line 3726, in _collect
    cls._tree(sort_cmd=sort_cmd, reverse=reverse, proc_per_cpu=proc_per_cpu, search=search)
  File "/usr/bin/bpytop", line 3968, in _tree
    create_tree(min(tree), tree)
                ^^^^^^^^^
ValueError: min() iterable argument is empty
23/08/24 (13:06:29) | WARNING: Exiting with errorcode (1). Runtime 0:03:19 

30/08/24 (22:38:18) | ERROR: <urlopen error timed out>
Traceback (most recent call last):
  File "/usr/lib/python3.12/urllib/request.py", line 1344, in do_open
    h.request(req.get_method(), req.selector, req.data, headers,
  File "/usr/lib/python3.12/http/client.py", line 1336, in request
    self._send_request(method, url, body, headers, encode_chunked)
  File "/usr/lib/python3.12/http/client.py", line 1382, in _send_request
    self.endheaders(body, encode_chunked=encode_chunked)
  File "/usr/lib/python3.12/http/client.py", line 1331, in endheaders
    self._send_output(message_body, encode_chunked=encode_chunked)
  File "/usr/lib/python3.12/http/client.py", line 1091, in _send_output
    self.send(msg)
  File "/usr/lib/python3.12/http/client.py", line 1035, in send
    self.connect()
  File "/usr/lib/python3.12/http/client.py", line 1470, in connect
    super().connect()
  File "/usr/lib/python3.12/http/client.py", line 1001, in connect
    self.sock = self._create_connection(
                ^^^^^^^^^^^^^^^^^^^^^^^^
  File "/usr/lib/python3.12/socket.py", line 865, in create_connection
    raise exceptions[0]
  File "/usr/lib/python3.12/socket.py", line 850, in create_connection
    sock.connect(sa)
TimeoutError: timed out

During handling of the above exception, another exception occurred:

Traceback (most recent call last):
  File "/usr/bin/bpytop", line 5029, in _checker
    with urllib.request.urlopen("https://github.com/aristocratos/bpytop/raw/master/bpytop.py", timeout=5) as source: # type: ignore
         ^^^^^^^^^^^^^^^^^^^^^^^^^^^^^^^^^^^^^^^^^^^^^^^^^^^^^^^^^^^^^^^^^^^^^^^^^^^^^^^^^^^^^^^^^^^^^^^^
  File "/usr/lib/python3.12/urllib/request.py", line 215, in urlopen
    return opener.open(url, data, timeout)
           ^^^^^^^^^^^^^^^^^^^^^^^^^^^^^^^
  File "/usr/lib/python3.12/urllib/request.py", line 515, in open
    response = self._open(req, data)
               ^^^^^^^^^^^^^^^^^^^^^
  File "/usr/lib/python3.12/urllib/request.py", line 532, in _open
    result = self._call_chain(self.handle_open, protocol, protocol +
             ^^^^^^^^^^^^^^^^^^^^^^^^^^^^^^^^^^^^^^^^^^^^^^^^^^^^^^^
  File "/usr/lib/python3.12/urllib/request.py", line 492, in _call_chain
    result = func(*args)
             ^^^^^^^^^^^
  File "/usr/lib/python3.12/urllib/request.py", line 1392, in https_open
    return self.do_open(http.client.HTTPSConnection, req,
           ^^^^^^^^^^^^^^^^^^^^^^^^^^^^^^^^^^^^^^^^^^^^^^
  File "/usr/lib/python3.12/urllib/request.py", line 1347, in do_open
    raise URLError(err)
urllib.error.URLError: <urlopen error timed out>
31/08/24 (11:09:47) | ERROR: Data collection thread failed with exception: cannot access local variable 'cmd' where it is not associated with a value
Traceback (most recent call last):
  File "/usr/bin/bpytop", line 2958, in _runner
    collector._collect()
  File "/usr/bin/bpytop", line 3726, in _collect
    cls._tree(sort_cmd=sort_cmd, reverse=reverse, proc_per_cpu=proc_per_cpu, search=search)
  File "/usr/bin/bpytop", line 3968, in _tree
    create_tree(min(tree), tree)
  File "/usr/bin/bpytop", line 3947, in create_tree
    "cmd" : cmd,
            ^^^
UnboundLocalError: cannot access local variable 'cmd' where it is not associated with a value
31/08/24 (11:09:47) | WARNING: Exiting with errorcode (1). Runtime 0:07:34 

27/10/24 (02:15:10) | ERROR: <urlopen error [Errno -3] Temporary failure in name resolution>
Traceback (most recent call last):
  File "/usr/lib/python3.12/urllib/request.py", line 1344, in do_open
    h.request(req.get_method(), req.selector, req.data, headers,
  File "/usr/lib/python3.12/http/client.py", line 1336, in request
    self._send_request(method, url, body, headers, encode_chunked)
  File "/usr/lib/python3.12/http/client.py", line 1382, in _send_request
    self.endheaders(body, encode_chunked=encode_chunked)
  File "/usr/lib/python3.12/http/client.py", line 1331, in endheaders
    self._send_output(message_body, encode_chunked=encode_chunked)
  File "/usr/lib/python3.12/http/client.py", line 1091, in _send_output
    self.send(msg)
  File "/usr/lib/python3.12/http/client.py", line 1035, in send
    self.connect()
  File "/usr/lib/python3.12/http/client.py", line 1470, in connect
    super().connect()
  File "/usr/lib/python3.12/http/client.py", line 1001, in connect
    self.sock = self._create_connection(
                ^^^^^^^^^^^^^^^^^^^^^^^^
  File "/usr/lib/python3.12/socket.py", line 841, in create_connection
    for res in getaddrinfo(host, port, 0, SOCK_STREAM):
               ^^^^^^^^^^^^^^^^^^^^^^^^^^^^^^^^^^^^^^^
  File "/usr/lib/python3.12/socket.py", line 976, in getaddrinfo
    for res in _socket.getaddrinfo(host, port, family, type, proto, flags):
               ^^^^^^^^^^^^^^^^^^^^^^^^^^^^^^^^^^^^^^^^^^^^^^^^^^^^^^^^^^^
socket.gaierror: [Errno -3] Temporary failure in name resolution

During handling of the above exception, another exception occurred:

Traceback (most recent call last):
  File "/usr/bin/bpytop", line 5029, in _checker
    with urllib.request.urlopen("https://github.com/aristocratos/bpytop/raw/master/bpytop.py", timeout=5) as source: # type: ignore
         ^^^^^^^^^^^^^^^^^^^^^^^^^^^^^^^^^^^^^^^^^^^^^^^^^^^^^^^^^^^^^^^^^^^^^^^^^^^^^^^^^^^^^^^^^^^^^^^^
  File "/usr/lib/python3.12/urllib/request.py", line 215, in urlopen
    return opener.open(url, data, timeout)
           ^^^^^^^^^^^^^^^^^^^^^^^^^^^^^^^
  File "/usr/lib/python3.12/urllib/request.py", line 515, in open
    response = self._open(req, data)
               ^^^^^^^^^^^^^^^^^^^^^
  File "/usr/lib/python3.12/urllib/request.py", line 532, in _open
    result = self._call_chain(self.handle_open, protocol, protocol +
             ^^^^^^^^^^^^^^^^^^^^^^^^^^^^^^^^^^^^^^^^^^^^^^^^^^^^^^^
  File "/usr/lib/python3.12/urllib/request.py", line 492, in _call_chain
    result = func(*args)
             ^^^^^^^^^^^
  File "/usr/lib/python3.12/urllib/request.py", line 1392, in https_open
    return self.do_open(http.client.HTTPSConnection, req,
           ^^^^^^^^^^^^^^^^^^^^^^^^^^^^^^^^^^^^^^^^^^^^^^
  File "/usr/lib/python3.12/urllib/request.py", line 1347, in do_open
    raise URLError(err)
urllib.error.URLError: <urlopen error [Errno -3] Temporary failure in name resolution>
12/11/24 (13:30:49) | ERROR: <urlopen error [Errno -3] Temporary failure in name resolution>
Traceback (most recent call last):
  File "/usr/lib/python3.12/urllib/request.py", line 1344, in do_open
    h.request(req.get_method(), req.selector, req.data, headers,
  File "/usr/lib/python3.12/http/client.py", line 1336, in request
    self._send_request(method, url, body, headers, encode_chunked)
  File "/usr/lib/python3.12/http/client.py", line 1382, in _send_request
    self.endheaders(body, encode_chunked=encode_chunked)
  File "/usr/lib/python3.12/http/client.py", line 1331, in endheaders
    self._send_output(message_body, encode_chunked=encode_chunked)
  File "/usr/lib/python3.12/http/client.py", line 1091, in _send_output
    self.send(msg)
  File "/usr/lib/python3.12/http/client.py", line 1035, in send
    self.connect()
  File "/usr/lib/python3.12/http/client.py", line 1470, in connect
    super().connect()
  File "/usr/lib/python3.12/http/client.py", line 1001, in connect
    self.sock = self._create_connection(
                ^^^^^^^^^^^^^^^^^^^^^^^^
  File "/usr/lib/python3.12/socket.py", line 841, in create_connection
    for res in getaddrinfo(host, port, 0, SOCK_STREAM):
               ^^^^^^^^^^^^^^^^^^^^^^^^^^^^^^^^^^^^^^^
  File "/usr/lib/python3.12/socket.py", line 976, in getaddrinfo
    for res in _socket.getaddrinfo(host, port, family, type, proto, flags):
               ^^^^^^^^^^^^^^^^^^^^^^^^^^^^^^^^^^^^^^^^^^^^^^^^^^^^^^^^^^^
socket.gaierror: [Errno -3] Temporary failure in name resolution

During handling of the above exception, another exception occurred:

Traceback (most recent call last):
  File "/usr/bin/bpytop", line 5029, in _checker
    with urllib.request.urlopen("https://github.com/aristocratos/bpytop/raw/master/bpytop.py", timeout=5) as source: # type: ignore
         ^^^^^^^^^^^^^^^^^^^^^^^^^^^^^^^^^^^^^^^^^^^^^^^^^^^^^^^^^^^^^^^^^^^^^^^^^^^^^^^^^^^^^^^^^^^^^^^^
  File "/usr/lib/python3.12/urllib/request.py", line 215, in urlopen
    return opener.open(url, data, timeout)
           ^^^^^^^^^^^^^^^^^^^^^^^^^^^^^^^
  File "/usr/lib/python3.12/urllib/request.py", line 515, in open
    response = self._open(req, data)
               ^^^^^^^^^^^^^^^^^^^^^
  File "/usr/lib/python3.12/urllib/request.py", line 532, in _open
    result = self._call_chain(self.handle_open, protocol, protocol +
             ^^^^^^^^^^^^^^^^^^^^^^^^^^^^^^^^^^^^^^^^^^^^^^^^^^^^^^^
  File "/usr/lib/python3.12/urllib/request.py", line 492, in _call_chain
    result = func(*args)
             ^^^^^^^^^^^
  File "/usr/lib/python3.12/urllib/request.py", line 1392, in https_open
    return self.do_open(http.client.HTTPSConnection, req,
           ^^^^^^^^^^^^^^^^^^^^^^^^^^^^^^^^^^^^^^^^^^^^^^
  File "/usr/lib/python3.12/urllib/request.py", line 1347, in do_open
    raise URLError(err)
urllib.error.URLError: <urlopen error [Errno -3] Temporary failure in name resolution>
13/11/24 (22:53:14) | ERROR: Exception when sending signal 9 to pid 852
13/11/24 (22:53:14) | ERROR: [Errno 1] Operation not permitted
Traceback (most recent call last):
  File "/usr/bin/bpytop", line 5479, in process_keys
    os.kill(pid, sig)
PermissionError: [Errno 1] Operation not permitted
13/11/24 (22:53:20) | ERROR: Exception when sending signal 9 to pid 852
13/11/24 (22:53:20) | ERROR: [Errno 1] Operation not permitted
Traceback (most recent call last):
  File "/usr/bin/bpytop", line 5479, in process_keys
    os.kill(pid, sig)
PermissionError: [Errno 1] Operation not permitted
13/11/24 (22:55:05) | ERROR: Exception when sending signal 9 to pid 15158
13/11/24 (22:55:05) | ERROR: [Errno 1] Operation not permitted
Traceback (most recent call last):
  File "/usr/bin/bpytop", line 5479, in process_keys
    os.kill(pid, sig)
PermissionError: [Errno 1] Operation not permitted
15/11/24 (22:22:59) | ERROR: Exception when sending signal 9 to pid 18941
15/11/24 (22:22:59) | ERROR: [Errno 1] Operation not permitted
Traceback (most recent call last):
  File "/usr/bin/bpytop", line 5479, in process_keys
    os.kill(pid, sig)
PermissionError: [Errno 1] Operation not permitted
15/11/24 (22:23:04) | ERROR: Exception when sending signal 9 to pid 18941
15/11/24 (22:23:04) | ERROR: [Errno 1] Operation not permitted
Traceback (most recent call last):
  File "/usr/bin/bpytop", line 5479, in process_keys
    os.kill(pid, sig)
PermissionError: [Errno 1] Operation not permitted
15/11/24 (22:24:14) | ERROR: Data collection thread failed with exception: Precision not allowed in integer format specifier
Traceback (most recent call last):
  File "/usr/bin/bpytop", line 2959, in _runner
    collector._draw()
  File "/usr/bin/bpytop", line 3991, in _draw
    ProcBox._draw_fg()
  File "/usr/bin/bpytop", line 2771, in _draw_fg
    (f'{proc.details["threads"]:^{iw}.{iw2}}' if expand > 0 else "") + (f'{proc.details["nice"]:^{iw}.{iw2}}' if expand > 1 else "") +
                                                                          ^^^^^^^^^^^^^^^^^^^^^^^^^^^^^^^^^^
ValueError: Precision not allowed in integer format specifier
15/11/24 (22:24:16) | WARNING: Exiting with errorcode (1). Runtime 0:02:07 

02/12/24 (13:37:32) | ERROR: Data collection thread failed with exception: cannot access local variable 'cmd' where it is not associated with a value
Traceback (most recent call last):
  File "/usr/bin/bpytop", line 2958, in _runner
    collector._collect()
  File "/usr/bin/bpytop", line 3726, in _collect
    cls._tree(sort_cmd=sort_cmd, reverse=reverse, proc_per_cpu=proc_per_cpu, search=search)
  File "/usr/bin/bpytop", line 3968, in _tree
    create_tree(min(tree), tree)
  File "/usr/bin/bpytop", line 3947, in create_tree
    "cmd" : cmd,
            ^^^
UnboundLocalError: cannot access local variable 'cmd' where it is not associated with a value
02/12/24 (13:37:34) | WARNING: Exiting with errorcode (1). Runtime 1 day, 10:43:01 

20/12/24 (15:11:57) | ERROR: <urlopen error [Errno 104] Connection reset by peer>
Traceback (most recent call last):
  File "/usr/lib/python3.12/urllib/request.py", line 1344, in do_open
    h.request(req.get_method(), req.selector, req.data, headers,
  File "/usr/lib/python3.12/http/client.py", line 1336, in request
    self._send_request(method, url, body, headers, encode_chunked)
  File "/usr/lib/python3.12/http/client.py", line 1382, in _send_request
    self.endheaders(body, encode_chunked=encode_chunked)
  File "/usr/lib/python3.12/http/client.py", line 1331, in endheaders
    self._send_output(message_body, encode_chunked=encode_chunked)
  File "/usr/lib/python3.12/http/client.py", line 1091, in _send_output
    self.send(msg)
  File "/usr/lib/python3.12/http/client.py", line 1035, in send
    self.connect()
  File "/usr/lib/python3.12/http/client.py", line 1477, in connect
    self.sock = self._context.wrap_socket(self.sock,
                ^^^^^^^^^^^^^^^^^^^^^^^^^^^^^^^^^^^^
  File "/usr/lib/python3.12/ssl.py", line 455, in wrap_socket
    return self.sslsocket_class._create(
           ^^^^^^^^^^^^^^^^^^^^^^^^^^^^^
  File "/usr/lib/python3.12/ssl.py", line 1041, in _create
    self.do_handshake()
  File "/usr/lib/python3.12/ssl.py", line 1319, in do_handshake
    self._sslobj.do_handshake()
ConnectionResetError: [Errno 104] Connection reset by peer

During handling of the above exception, another exception occurred:

Traceback (most recent call last):
  File "/usr/bin/bpytop", line 5029, in _checker
    with urllib.request.urlopen("https://github.com/aristocratos/bpytop/raw/master/bpytop.py", timeout=5) as source: # type: ignore
         ^^^^^^^^^^^^^^^^^^^^^^^^^^^^^^^^^^^^^^^^^^^^^^^^^^^^^^^^^^^^^^^^^^^^^^^^^^^^^^^^^^^^^^^^^^^^^^^^
  File "/usr/lib/python3.12/urllib/request.py", line 215, in urlopen
    return opener.open(url, data, timeout)
           ^^^^^^^^^^^^^^^^^^^^^^^^^^^^^^^
  File "/usr/lib/python3.12/urllib/request.py", line 521, in open
    response = meth(req, response)
               ^^^^^^^^^^^^^^^^^^^
  File "/usr/lib/python3.12/urllib/request.py", line 630, in http_response
    response = self.parent.error(
               ^^^^^^^^^^^^^^^^^^
  File "/usr/lib/python3.12/urllib/request.py", line 553, in error
    result = self._call_chain(*args)
             ^^^^^^^^^^^^^^^^^^^^^^^
  File "/usr/lib/python3.12/urllib/request.py", line 492, in _call_chain
    result = func(*args)
             ^^^^^^^^^^^
  File "/usr/lib/python3.12/urllib/request.py", line 745, in http_error_302
    return self.parent.open(new, timeout=req.timeout)
           ^^^^^^^^^^^^^^^^^^^^^^^^^^^^^^^^^^^^^^^^^^
  File "/usr/lib/python3.12/urllib/request.py", line 515, in open
    response = self._open(req, data)
               ^^^^^^^^^^^^^^^^^^^^^
  File "/usr/lib/python3.12/urllib/request.py", line 532, in _open
    result = self._call_chain(self.handle_open, protocol, protocol +
             ^^^^^^^^^^^^^^^^^^^^^^^^^^^^^^^^^^^^^^^^^^^^^^^^^^^^^^^
  File "/usr/lib/python3.12/urllib/request.py", line 492, in _call_chain
    result = func(*args)
             ^^^^^^^^^^^
  File "/usr/lib/python3.12/urllib/request.py", line 1392, in https_open
    return self.do_open(http.client.HTTPSConnection, req,
           ^^^^^^^^^^^^^^^^^^^^^^^^^^^^^^^^^^^^^^^^^^^^^^
  File "/usr/lib/python3.12/urllib/request.py", line 1347, in do_open
    raise URLError(err)
urllib.error.URLError: <urlopen error [Errno 104] Connection reset by peer>
20/12/24 (16:13:48) | ERROR: Remote end closed connection without response
Traceback (most recent call last):
  File "/usr/bin/bpytop", line 5029, in _checker
    with urllib.request.urlopen("https://github.com/aristocratos/bpytop/raw/master/bpytop.py", timeout=5) as source: # type: ignore
         ^^^^^^^^^^^^^^^^^^^^^^^^^^^^^^^^^^^^^^^^^^^^^^^^^^^^^^^^^^^^^^^^^^^^^^^^^^^^^^^^^^^^^^^^^^^^^^^^
  File "/usr/lib/python3.12/urllib/request.py", line 215, in urlopen
    return opener.open(url, data, timeout)
           ^^^^^^^^^^^^^^^^^^^^^^^^^^^^^^^
  File "/usr/lib/python3.12/urllib/request.py", line 521, in open
    response = meth(req, response)
               ^^^^^^^^^^^^^^^^^^^
  File "/usr/lib/python3.12/urllib/request.py", line 630, in http_response
    response = self.parent.error(
               ^^^^^^^^^^^^^^^^^^
  File "/usr/lib/python3.12/urllib/request.py", line 553, in error
    result = self._call_chain(*args)
             ^^^^^^^^^^^^^^^^^^^^^^^
  File "/usr/lib/python3.12/urllib/request.py", line 492, in _call_chain
    result = func(*args)
             ^^^^^^^^^^^
  File "/usr/lib/python3.12/urllib/request.py", line 745, in http_error_302
    return self.parent.open(new, timeout=req.timeout)
           ^^^^^^^^^^^^^^^^^^^^^^^^^^^^^^^^^^^^^^^^^^
  File "/usr/lib/python3.12/urllib/request.py", line 515, in open
    response = self._open(req, data)
               ^^^^^^^^^^^^^^^^^^^^^
  File "/usr/lib/python3.12/urllib/request.py", line 532, in _open
    result = self._call_chain(self.handle_open, protocol, protocol +
             ^^^^^^^^^^^^^^^^^^^^^^^^^^^^^^^^^^^^^^^^^^^^^^^^^^^^^^^
  File "/usr/lib/python3.12/urllib/request.py", line 492, in _call_chain
    result = func(*args)
             ^^^^^^^^^^^
  File "/usr/lib/python3.12/urllib/request.py", line 1392, in https_open
    return self.do_open(http.client.HTTPSConnection, req,
           ^^^^^^^^^^^^^^^^^^^^^^^^^^^^^^^^^^^^^^^^^^^^^^
  File "/usr/lib/python3.12/urllib/request.py", line 1348, in do_open
    r = h.getresponse()
        ^^^^^^^^^^^^^^^
  File "/usr/lib/python3.12/http/client.py", line 1428, in getresponse
    response.begin()
  File "/usr/lib/python3.12/http/client.py", line 331, in begin
    version, status, reason = self._read_status()
                              ^^^^^^^^^^^^^^^^^^^
  File "/usr/lib/python3.12/http/client.py", line 300, in _read_status
    raise RemoteDisconnected("Remote end closed connection without"
http.client.RemoteDisconnected: Remote end closed connection without response
22/12/24 (19:04:13) | ERROR: [Errno 104] Connection reset by peer
Traceback (most recent call last):
  File "/usr/bin/bpytop", line 5029, in _checker
    with urllib.request.urlopen("https://github.com/aristocratos/bpytop/raw/master/bpytop.py", timeout=5) as source: # type: ignore
         ~~~~~~~~~~~~~~~~~~~~~~^^^^^^^^^^^^^^^^^^^^^^^^^^^^^^^^^^^^^^^^^^^^^^^^^^^^^^^^^^^^^^^^^^^^^^^^^^
  File "/usr/lib/python3.13/urllib/request.py", line 189, in urlopen
    return opener.open(url, data, timeout)
           ~~~~~~~~~~~^^^^^^^^^^^^^^^^^^^^
  File "/usr/lib/python3.13/urllib/request.py", line 495, in open
    response = meth(req, response)
  File "/usr/lib/python3.13/urllib/request.py", line 604, in http_response
    response = self.parent.error(
        'http', request, response, code, msg, hdrs)
  File "/usr/lib/python3.13/urllib/request.py", line 527, in error
    result = self._call_chain(*args)
  File "/usr/lib/python3.13/urllib/request.py", line 466, in _call_chain
    result = func(*args)
  File "/usr/lib/python3.13/urllib/request.py", line 720, in http_error_302
    return self.parent.open(new, timeout=req.timeout)
           ~~~~~~~~~~~~~~~~^^^^^^^^^^^^^^^^^^^^^^^^^^
  File "/usr/lib/python3.13/urllib/request.py", line 489, in open
    response = self._open(req, data)
  File "/usr/lib/python3.13/urllib/request.py", line 506, in _open
    result = self._call_chain(self.handle_open, protocol, protocol +
                              '_open', req)
  File "/usr/lib/python3.13/urllib/request.py", line 466, in _call_chain
    result = func(*args)
  File "/usr/lib/python3.13/urllib/request.py", line 1367, in https_open
    return self.do_open(http.client.HTTPSConnection, req,
           ~~~~~~~~~~~~^^^^^^^^^^^^^^^^^^^^^^^^^^^^^^^^^^
                        context=self._context)
                        ^^^^^^^^^^^^^^^^^^^^^^
  File "/usr/lib/python3.13/urllib/request.py", line 1323, in do_open
    r = h.getresponse()
  File "/usr/lib/python3.13/http/client.py", line 1428, in getresponse
    response.begin()
    ~~~~~~~~~~~~~~^^
  File "/usr/lib/python3.13/http/client.py", line 331, in begin
    version, status, reason = self._read_status()
                              ~~~~~~~~~~~~~~~~~^^
  File "/usr/lib/python3.13/http/client.py", line 292, in _read_status
    line = str(self.fp.readline(_MAXLINE + 1), "iso-8859-1")
               ~~~~~~~~~~~~~~~~^^^^^^^^^^^^^^
  File "/usr/lib/python3.13/socket.py", line 719, in readinto
    return self._sock.recv_into(b)
           ~~~~~~~~~~~~~~~~~~~~^^^
  File "/usr/lib/python3.13/ssl.py", line 1304, in recv_into
    return self.read(nbytes, buffer)
           ~~~~~~~~~^^^^^^^^^^^^^^^^
  File "/usr/lib/python3.13/ssl.py", line 1138, in read
    return self._sslobj.read(len, buffer)
           ~~~~~~~~~~~~~~~~~^^^^^^^^^^^^^
ConnectionResetError: [Errno 104] Connection reset by peer
13/02/25 (20:13:53) | ERROR: <urlopen error timed out>
Traceback (most recent call last):
  File "/usr/lib/python3.13/urllib/request.py", line 1319, in do_open
    h.request(req.get_method(), req.selector, req.data, headers,
    ~~~~~~~~~^^^^^^^^^^^^^^^^^^^^^^^^^^^^^^^^^^^^^^^^^^^^^^^^^^^
              encode_chunked=req.has_header('Transfer-encoding'))
              ^^^^^^^^^^^^^^^^^^^^^^^^^^^^^^^^^^^^^^^^^^^^^^^^^^^
  File "/usr/lib/python3.13/http/client.py", line 1336, in request
    self._send_request(method, url, body, headers, encode_chunked)
    ~~~~~~~~~~~~~~~~~~^^^^^^^^^^^^^^^^^^^^^^^^^^^^^^^^^^^^^^^^^^^^
  File "/usr/lib/python3.13/http/client.py", line 1382, in _send_request
    self.endheaders(body, encode_chunked=encode_chunked)
    ~~~~~~~~~~~~~~~^^^^^^^^^^^^^^^^^^^^^^^^^^^^^^^^^^^^^
  File "/usr/lib/python3.13/http/client.py", line 1331, in endheaders
    self._send_output(message_body, encode_chunked=encode_chunked)
    ~~~~~~~~~~~~~~~~~^^^^^^^^^^^^^^^^^^^^^^^^^^^^^^^^^^^^^^^^^^^^^
  File "/usr/lib/python3.13/http/client.py", line 1091, in _send_output
    self.send(msg)
    ~~~~~~~~~^^^^^
  File "/usr/lib/python3.13/http/client.py", line 1035, in send
    self.connect()
    ~~~~~~~~~~~~^^
  File "/usr/lib/python3.13/http/client.py", line 1470, in connect
    super().connect()
    ~~~~~~~~~~~~~~~^^
  File "/usr/lib/python3.13/http/client.py", line 1001, in connect
    self.sock = self._create_connection(
                ~~~~~~~~~~~~~~~~~~~~~~~^
        (self.host,self.port), self.timeout, self.source_address)
        ^^^^^^^^^^^^^^^^^^^^^^^^^^^^^^^^^^^^^^^^^^^^^^^^^^^^^^^^^
  File "/usr/lib/python3.13/socket.py", line 864, in create_connection
    raise exceptions[0]
  File "/usr/lib/python3.13/socket.py", line 849, in create_connection
    sock.connect(sa)
    ~~~~~~~~~~~~^^^^
TimeoutError: timed out

During handling of the above exception, another exception occurred:

Traceback (most recent call last):
  File "/usr/bin/bpytop", line 5029, in _checker
    with urllib.request.urlopen("https://github.com/aristocratos/bpytop/raw/master/bpytop.py", timeout=5) as source: # type: ignore
         ~~~~~~~~~~~~~~~~~~~~~~^^^^^^^^^^^^^^^^^^^^^^^^^^^^^^^^^^^^^^^^^^^^^^^^^^^^^^^^^^^^^^^^^^^^^^^^^^
  File "/usr/lib/python3.13/urllib/request.py", line 189, in urlopen
    return opener.open(url, data, timeout)
           ~~~~~~~~~~~^^^^^^^^^^^^^^^^^^^^
  File "/usr/lib/python3.13/urllib/request.py", line 489, in open
    response = self._open(req, data)
  File "/usr/lib/python3.13/urllib/request.py", line 506, in _open
    result = self._call_chain(self.handle_open, protocol, protocol +
                              '_open', req)
  File "/usr/lib/python3.13/urllib/request.py", line 466, in _call_chain
    result = func(*args)
  File "/usr/lib/python3.13/urllib/request.py", line 1367, in https_open
    return self.do_open(http.client.HTTPSConnection, req,
           ~~~~~~~~~~~~^^^^^^^^^^^^^^^^^^^^^^^^^^^^^^^^^^
                        context=self._context)
                        ^^^^^^^^^^^^^^^^^^^^^^
  File "/usr/lib/python3.13/urllib/request.py", line 1322, in do_open
    raise URLError(err)
urllib.error.URLError: <urlopen error timed out>
08/04/25 (22:54:34) | ERROR: Data collection thread failed with exception: min() iterable argument is empty
Traceback (most recent call last):
  File "/usr/bin/bpytop", line 2958, in _runner
    collector._collect()
    ~~~~~~~~~~~~~~~~~~^^
  File "/usr/bin/bpytop", line 3726, in _collect
    cls._tree(sort_cmd=sort_cmd, reverse=reverse, proc_per_cpu=proc_per_cpu, search=search)
    ~~~~~~~~~^^^^^^^^^^^^^^^^^^^^^^^^^^^^^^^^^^^^^^^^^^^^^^^^^^^^^^^^^^^^^^^^^^^^^^^^^^^^^^
  File "/usr/bin/bpytop", line 3968, in _tree
    create_tree(min(tree), tree)
                ~~~^^^^^^
ValueError: min() iterable argument is empty
08/04/25 (22:54:36) | WARNING: Exiting with errorcode (1). Runtime 3:03:48 

09/04/25 (00:21:53) | ERROR: <urlopen error timed out>
Traceback (most recent call last):
  File "/usr/lib/python3.13/urllib/request.py", line 1319, in do_open
    h.request(req.get_method(), req.selector, req.data, headers,
    ~~~~~~~~~^^^^^^^^^^^^^^^^^^^^^^^^^^^^^^^^^^^^^^^^^^^^^^^^^^^
              encode_chunked=req.has_header('Transfer-encoding'))
              ^^^^^^^^^^^^^^^^^^^^^^^^^^^^^^^^^^^^^^^^^^^^^^^^^^^
  File "/usr/lib/python3.13/http/client.py", line 1338, in request
    self._send_request(method, url, body, headers, encode_chunked)
    ~~~~~~~~~~~~~~~~~~^^^^^^^^^^^^^^^^^^^^^^^^^^^^^^^^^^^^^^^^^^^^
  File "/usr/lib/python3.13/http/client.py", line 1384, in _send_request
    self.endheaders(body, encode_chunked=encode_chunked)
    ~~~~~~~~~~~~~~~^^^^^^^^^^^^^^^^^^^^^^^^^^^^^^^^^^^^^
  File "/usr/lib/python3.13/http/client.py", line 1333, in endheaders
    self._send_output(message_body, encode_chunked=encode_chunked)
    ~~~~~~~~~~~~~~~~~^^^^^^^^^^^^^^^^^^^^^^^^^^^^^^^^^^^^^^^^^^^^^
  File "/usr/lib/python3.13/http/client.py", line 1093, in _send_output
    self.send(msg)
    ~~~~~~~~~^^^^^
  File "/usr/lib/python3.13/http/client.py", line 1037, in send
    self.connect()
    ~~~~~~~~~~~~^^
  File "/usr/lib/python3.13/http/client.py", line 1472, in connect
    super().connect()
    ~~~~~~~~~~~~~~~^^
  File "/usr/lib/python3.13/http/client.py", line 1003, in connect
    self.sock = self._create_connection(
                ~~~~~~~~~~~~~~~~~~~~~~~^
        (self.host,self.port), self.timeout, self.source_address)
        ^^^^^^^^^^^^^^^^^^^^^^^^^^^^^^^^^^^^^^^^^^^^^^^^^^^^^^^^^
  File "/usr/lib/python3.13/socket.py", line 864, in create_connection
    raise exceptions[0]
  File "/usr/lib/python3.13/socket.py", line 849, in create_connection
    sock.connect(sa)
    ~~~~~~~~~~~~^^^^
TimeoutError: timed out

During handling of the above exception, another exception occurred:

Traceback (most recent call last):
  File "/usr/bin/bpytop", line 5029, in _checker
    with urllib.request.urlopen("https://github.com/aristocratos/bpytop/raw/master/bpytop.py", timeout=5) as source: # type: ignore
         ~~~~~~~~~~~~~~~~~~~~~~^^^^^^^^^^^^^^^^^^^^^^^^^^^^^^^^^^^^^^^^^^^^^^^^^^^^^^^^^^^^^^^^^^^^^^^^^^
  File "/usr/lib/python3.13/urllib/request.py", line 189, in urlopen
    return opener.open(url, data, timeout)
           ~~~~~~~~~~~^^^^^^^^^^^^^^^^^^^^
  File "/usr/lib/python3.13/urllib/request.py", line 489, in open
    response = self._open(req, data)
  File "/usr/lib/python3.13/urllib/request.py", line 506, in _open
    result = self._call_chain(self.handle_open, protocol, protocol +
                              '_open', req)
  File "/usr/lib/python3.13/urllib/request.py", line 466, in _call_chain
    result = func(*args)
  File "/usr/lib/python3.13/urllib/request.py", line 1367, in https_open
    return self.do_open(http.client.HTTPSConnection, req,
           ~~~~~~~~~~~~^^^^^^^^^^^^^^^^^^^^^^^^^^^^^^^^^^
                        context=self._context)
                        ^^^^^^^^^^^^^^^^^^^^^^
  File "/usr/lib/python3.13/urllib/request.py", line 1322, in do_open
    raise URLError(err)
urllib.error.URLError: <urlopen error timed out>
